# -*- coding: utf-8 -*-
from asyncy.Exceptions import AsyncyError, TooManyActiveApps, \
    TooManyServices, TooManyVolumes

from pytest import mark, raises


def test_asyncy_error():
    with raises(AsyncyError):
        raise AsyncyError('things happen')


def test_many_volumes():
    with raises(TooManyVolumes):
        raise TooManyVolumes(10, 10)


def test_many_apps():
    with raises(TooManyActiveApps):
        raise TooManyActiveApps(10, 10)


def test_no_trace_available():
    err = AsyncyError(message='my_message')
    assert str(err) == 'AsyncyError: my_message'


@mark.parametrize('with_root', [True, False])
def test_exception_trace(magic, patch, story, with_root):
    root_message = 'test'
    root = BaseException(root_message)

    if not with_root:
        root = None
        root_message = ''

    patch.object(story, 'get_stack', return_value=['1', '2', '3'])

    patch.object(story, 'line', side_effect=[
        {'src': 'line_1'}, {'method': 'hello'}, {'src': 'line_3'}])

    story.name = 'story_name'

    ex = AsyncyError(message='unknown error',
                     story=story, line=magic(), root=root)

    # We cache the result of str(ex) because if we don't, __str__ will run
    # again, and will then throw a StopIteration exception since
    # pytest mocks the function `line` above.
    str_version = str(ex)
    if root_message:
        root_message = f': {root_message}'
    assert str_version == f"""An exception has occurred:
unknown error{root_message}
    at line 1: line_1 (in story_name)
    at line 2: method=hello (auto generated frame) (in story_name)
    at line 3: line_3 (in story_name)"""


def test_many_services():
    with raises(TooManyServices):
        raise TooManyServices(10, 10)
